2022-08-03 04:39:15,525 ERROR: Exception on /login [GET] [in /usr/local/lib/python3.9/site-packages/flask/app.py:1455]
Traceback (most recent call last):
  File "/usr/local/lib/python3.9/site-packages/flask/app.py", line 2077, in wsgi_app
    response = self.full_dispatch_request()
  File "/usr/local/lib/python3.9/site-packages/flask/app.py", line 1525, in full_dispatch_request
    rv = self.handle_user_exception(e)
  File "/usr/local/lib/python3.9/site-packages/flask/app.py", line 1523, in full_dispatch_request
    rv = self.dispatch_request()
  File "/usr/local/lib/python3.9/site-packages/flask/app.py", line 1509, in dispatch_request
    return self.ensure_sync(self.view_functions[rule.endpoint])(**req.view_args)
  File "/root/python/flask/app/routes.py", line 55, in login
    return render_template('login.html',title=_('Sign In'), form=form)
  File "/usr/local/lib/python3.9/site-packages/flask/templating.py", line 149, in render_template
    ctx.app.jinja_env.get_or_select_template(template_name_or_list),
  File "/usr/local/lib/python3.9/site-packages/jinja2/environment.py", line 1081, in get_or_select_template
    return self.get_template(template_name_or_list, parent, globals)
  File "/usr/local/lib/python3.9/site-packages/jinja2/environment.py", line 1010, in get_template
    return self._load_template(name, globals)
  File "/usr/local/lib/python3.9/site-packages/jinja2/environment.py", line 969, in _load_template
    template = self.loader.load(self, name, self.make_globals(globals))
  File "/usr/local/lib/python3.9/site-packages/jinja2/loaders.py", line 138, in load
    code = environment.compile(source, name, filename)
  File "/usr/local/lib/python3.9/site-packages/jinja2/environment.py", line 768, in compile
    self.handle_exception(source=source_hint)
  File "/usr/local/lib/python3.9/site-packages/jinja2/environment.py", line 936, in handle_exception
    raise rewrite_traceback_stack(source=source)
  File "/root/python/flask/app/templates/login.html", line 14, in template
    {{ _('Forgot Your Password?') }}
jinja2.exceptions.TemplateSyntaxError: expected token ',', got 'Forgot'
2022-08-03 04:40:08,448 INFO: Microblog startup [in /root/python/flask/app/__init__.py:52]
2022-08-03 04:41:28,897 INFO: Microblog startup [in /root/python/flask/app/__init__.py:52]
2022-08-03 04:54:08,463 INFO: Microblog startup [in /root/python/flask/app/__init__.py:52]
2022-08-03 04:55:16,221 INFO: Microblog startup [in /root/python/flask/app/__init__.py:52]
2022-08-03 05:14:35,919 INFO: Microblog startup [in /root/python/flask/app/__init__.py:52]
2022-08-03 05:52:04,575 INFO: Microblog startup [in /root/python/flask/app/__init__.py:52]
2022-08-03 06:01:26,106 INFO: Microblog startup [in /root/python/flask/app/__init__.py:52]
2022-08-03 06:02:08,467 INFO: Microblog startup [in /root/python/flask/app/__init__.py:52]
2022-08-03 06:25:36,934 INFO: Microblog startup [in /root/python/flask/app/__init__.py:52]
2022-08-03 06:57:31,250 INFO: Microblog startup [in /root/python/flask/app/__init__.py:52]
2022-08-03 07:05:38,073 INFO: Microblog startup [in /root/python/flask/app/__init__.py:52]
2022-08-03 07:11:42,516 INFO: Microblog startup [in /root/python/flask/app/__init__.py:52]
2022-08-03 07:11:48,831 ERROR: Exception on /translate [POST] [in /usr/local/lib/python3.9/site-packages/flask/app.py:1455]
Traceback (most recent call last):
  File "/usr/local/lib/python3.9/site-packages/flask/app.py", line 2077, in wsgi_app
    response = self.full_dispatch_request()
  File "/usr/local/lib/python3.9/site-packages/flask/app.py", line 1525, in full_dispatch_request
    rv = self.handle_user_exception(e)
  File "/usr/local/lib/python3.9/site-packages/flask/app.py", line 1523, in full_dispatch_request
    rv = self.dispatch_request()
  File "/usr/local/lib/python3.9/site-packages/flask/app.py", line 1509, in dispatch_request
    return self.ensure_sync(self.view_functions[rule.endpoint])(**req.view_args)
  File "/usr/local/lib/python3.9/site-packages/flask_login/utils.py", line 303, in decorated_view
    return current_app.ensure_sync(func)(*args, **kwargs)
  File "/root/python/flask/app/routes.py", line 199, in translate_text
    return jsonify({'text': translate(request.form['text'],
NameError: name 'translate' is not defined
2022-08-03 07:15:20,482 INFO: Microblog startup [in /root/python/flask/app/__init__.py:52]
2022-08-03 08:59:22,801 INFO: Microblog startup [in /root/python/flask/app/__init__.py:55]
2022-08-03 12:27:25,759 INFO: Microblog startup [in /root/python/flask/app/__init__.py:73]
2022-08-03 12:27:41,276 ERROR: Exception on /translate [POST] [in /usr/local/lib/python3.9/site-packages/flask/app.py:1455]
Traceback (most recent call last):
  File "/usr/local/lib/python3.9/site-packages/flask/app.py", line 2077, in wsgi_app
    response = self.full_dispatch_request()
  File "/usr/local/lib/python3.9/site-packages/flask/app.py", line 1525, in full_dispatch_request
    rv = self.handle_user_exception(e)
  File "/usr/local/lib/python3.9/site-packages/flask/app.py", line 1523, in full_dispatch_request
    rv = self.dispatch_request()
  File "/usr/local/lib/python3.9/site-packages/flask/app.py", line 1509, in dispatch_request
    return self.ensure_sync(self.view_functions[rule.endpoint])(**req.view_args)
  File "/usr/local/lib/python3.9/site-packages/flask_login/utils.py", line 303, in decorated_view
    return current_app.ensure_sync(func)(*args, **kwargs)
  File "/root/python/flask/app/main/routes.py", line 141, in translate_text
    return jsonify({'text': translate(request.form['text'],
  File "/root/python/flask/app/translate.py", line 7, in translate
    if 'MS_TRANSLATOR_KEY' not in current.app.config or \
NameError: name 'current' is not defined
2022-08-03 12:28:21,370 ERROR: Exception on /auth/login [POST] [in /usr/local/lib/python3.9/site-packages/flask/app.py:1455]
Traceback (most recent call last):
  File "/usr/local/lib/python3.9/site-packages/flask/app.py", line 2077, in wsgi_app
    response = self.full_dispatch_request()
  File "/usr/local/lib/python3.9/site-packages/flask/app.py", line 1525, in full_dispatch_request
    rv = self.handle_user_exception(e)
  File "/usr/local/lib/python3.9/site-packages/flask/app.py", line 1523, in full_dispatch_request
    rv = self.dispatch_request()
  File "/usr/local/lib/python3.9/site-packages/flask/app.py", line 1509, in dispatch_request
    return self.ensure_sync(self.view_functions[rule.endpoint])(**req.view_args)
  File "/root/python/flask/app/auth/routes.py", line 21, in login
    login_user(user,remember=form.remember_me.data)
NameError: name 'login_user' is not defined
2022-08-03 12:30:44,717 INFO: Microblog startup [in /root/python/flask/app/__init__.py:73]
2022-08-03 12:31:47,595 ERROR: Exception on /translate [POST] [in /usr/local/lib/python3.9/site-packages/flask/app.py:1455]
Traceback (most recent call last):
  File "/usr/local/lib/python3.9/site-packages/flask/app.py", line 2077, in wsgi_app
    response = self.full_dispatch_request()
  File "/usr/local/lib/python3.9/site-packages/flask/app.py", line 1525, in full_dispatch_request
    rv = self.handle_user_exception(e)
  File "/usr/local/lib/python3.9/site-packages/flask/app.py", line 1523, in full_dispatch_request
    rv = self.dispatch_request()
  File "/usr/local/lib/python3.9/site-packages/flask/app.py", line 1509, in dispatch_request
    return self.ensure_sync(self.view_functions[rule.endpoint])(**req.view_args)
  File "/usr/local/lib/python3.9/site-packages/flask_login/utils.py", line 303, in decorated_view
    return current_app.ensure_sync(func)(*args, **kwargs)
  File "/root/python/flask/app/main/routes.py", line 141, in translate_text
    return jsonify({'text': translate(request.form['text'],
  File "/root/python/flask/app/translate.py", line 7, in translate
    if 'MS_TRANSLATOR_KEY' not in current.app.config or \
NameError: name 'current' is not defined
2022-08-03 12:32:05,279 ERROR: Exception on /translate [POST] [in /usr/local/lib/python3.9/site-packages/flask/app.py:1455]
Traceback (most recent call last):
  File "/usr/local/lib/python3.9/site-packages/flask/app.py", line 2077, in wsgi_app
    response = self.full_dispatch_request()
  File "/usr/local/lib/python3.9/site-packages/flask/app.py", line 1525, in full_dispatch_request
    rv = self.handle_user_exception(e)
  File "/usr/local/lib/python3.9/site-packages/flask/app.py", line 1523, in full_dispatch_request
    rv = self.dispatch_request()
  File "/usr/local/lib/python3.9/site-packages/flask/app.py", line 1509, in dispatch_request
    return self.ensure_sync(self.view_functions[rule.endpoint])(**req.view_args)
  File "/usr/local/lib/python3.9/site-packages/flask_login/utils.py", line 303, in decorated_view
    return current_app.ensure_sync(func)(*args, **kwargs)
  File "/root/python/flask/app/main/routes.py", line 141, in translate_text
    return jsonify({'text': translate(request.form['text'],
  File "/root/python/flask/app/translate.py", line 7, in translate
    if 'MS_TRANSLATOR_KEY' not in current.app.config or \
NameError: name 'current' is not defined
