2022-08-01 07:14:07,247 INFO: Microblog startup [in /root/python/flask/app/__init__.py:45]
2022-08-01 07:14:39,282 INFO: Microblog startup [in /root/python/flask/app/__init__.py:45]
2022-08-01 07:15:17,617 INFO: Microblog startup [in /root/python/flask/app/__init__.py:45]
2022-08-01 07:15:59,021 INFO: Microblog startup [in /root/python/flask/app/__init__.py:45]
2022-08-01 07:17:05,320 INFO: Microblog startup [in /root/python/flask/app/__init__.py:45]
2022-08-01 07:20:13,893 INFO: Microblog startup [in /root/python/flask/app/__init__.py:45]
2022-08-01 07:20:30,375 ERROR: Exception on /reset_password_request [POST] [in /usr/local/lib/python3.9/site-packages/flask/app.py:1455]
Traceback (most recent call last):
  File "/usr/local/lib/python3.9/site-packages/flask/app.py", line 2077, in wsgi_app
    response = self.full_dispatch_request()
  File "/usr/local/lib/python3.9/site-packages/flask/app.py", line 1525, in full_dispatch_request
    rv = self.handle_user_exception(e)
  File "/usr/local/lib/python3.9/site-packages/flask/app.py", line 1523, in full_dispatch_request
    rv = self.dispatch_request()
  File "/usr/local/lib/python3.9/site-packages/flask/app.py", line 1509, in dispatch_request
    return self.ensure_sync(self.view_functions[rule.endpoint])(**req.view_args)
  File "/root/python/flask/app/routes.py", line 164, in reset_password_request
    send_password_reset_email(user)
  File "/root/python/flask/app/email.py", line 11, in send_password_reset_email
    token=user.get_reset_password_token()
  File "/root/python/flask/app/models.py", line 63, in get_reset_password_token
    return jwt.encode(
TypeError: encode() got an unexpected keyword argument 'algorithms'
2022-08-01 07:22:26,721 INFO: Microblog startup [in /root/python/flask/app/__init__.py:45]
2022-08-01 07:22:43,106 ERROR: Exception on /reset_password_request [POST] [in /usr/local/lib/python3.9/site-packages/flask/app.py:1455]
Traceback (most recent call last):
  File "/usr/local/lib/python3.9/site-packages/flask/app.py", line 2077, in wsgi_app
    response = self.full_dispatch_request()
  File "/usr/local/lib/python3.9/site-packages/flask/app.py", line 1525, in full_dispatch_request
    rv = self.handle_user_exception(e)
  File "/usr/local/lib/python3.9/site-packages/flask/app.py", line 1523, in full_dispatch_request
    rv = self.dispatch_request()
  File "/usr/local/lib/python3.9/site-packages/flask/app.py", line 1509, in dispatch_request
    return self.ensure_sync(self.view_functions[rule.endpoint])(**req.view_args)
  File "/root/python/flask/app/routes.py", line 162, in reset_password_request
    send_password_reset_email(user)
  File "/root/python/flask/app/email.py", line 13, in send_password_reset_email
    sender=app.config['ADMINS'][0],
NameError: name 'app' is not defined
2022-08-01 07:24:07,760 INFO: Microblog startup [in /root/python/flask/app/__init__.py:45]
2022-08-01 07:24:41,687 INFO: Microblog startup [in /root/python/flask/app/__init__.py:45]
2022-08-01 07:24:55,358 ERROR: Exception on /reset_password_request [POST] [in /usr/local/lib/python3.9/site-packages/flask/app.py:1455]
Traceback (most recent call last):
  File "/usr/local/lib/python3.9/site-packages/flask/app.py", line 2077, in wsgi_app
    response = self.full_dispatch_request()
  File "/usr/local/lib/python3.9/site-packages/flask/app.py", line 1525, in full_dispatch_request
    rv = self.handle_user_exception(e)
  File "/usr/local/lib/python3.9/site-packages/flask/app.py", line 1523, in full_dispatch_request
    rv = self.dispatch_request()
  File "/usr/local/lib/python3.9/site-packages/flask/app.py", line 1509, in dispatch_request
    return self.ensure_sync(self.view_functions[rule.endpoint])(**req.view_args)
  File "/root/python/flask/app/routes.py", line 162, in reset_password_request
    send_password_reset_email(user)
  File "/root/python/flask/app/email.py", line 14, in send_password_reset_email
    send_email('[Microblog] Reset Your Password',
TypeError: send_email() got an unexpected keyword argument 'recipients'
2022-08-01 07:28:03,019 INFO: Microblog startup [in /root/python/flask/app/__init__.py:45]
2022-08-01 07:28:30,597 ERROR: Exception on /reset_password/eyJ0eXAiOiJKV1QiLCJhbGciOiJIUzI1NiJ9.eyJyZXNldF9wYXNzd29yZCI6MSwiZXhwIjoxNjU5MzUzODkxLjIyNTE5MjV9.Js8us_SbuieJ85-H3Z7lRH90fny_RQsumLY3feb59zo [GET] [in /usr/local/lib/python3.9/site-packages/flask/app.py:1455]
Traceback (most recent call last):
  File "/usr/local/lib/python3.9/site-packages/flask/app.py", line 2077, in wsgi_app
    response = self.full_dispatch_request()
  File "/usr/local/lib/python3.9/site-packages/flask/app.py", line 1525, in full_dispatch_request
    rv = self.handle_user_exception(e)
  File "/usr/local/lib/python3.9/site-packages/flask/app.py", line 1523, in full_dispatch_request
    rv = self.dispatch_request()
  File "/usr/local/lib/python3.9/site-packages/flask/app.py", line 1509, in dispatch_request
    return self.ensure_sync(self.view_functions[rule.endpoint])(**req.view_args)
  File "/root/python/flask/app/routes.py", line 176, in reset_password
    form=ResetPasswordForm()
NameError: name 'ResetPasswordForm' is not defined
2022-08-01 07:31:48,785 INFO: Microblog startup [in /root/python/flask/app/__init__.py:45]
2022-08-01 07:32:09,977 ERROR: Exception on /reset_password/eyJ0eXAiOiJKV1QiLCJhbGciOiJIUzI1NiJ9.eyJyZXNldF9wYXNzd29yZCI6MSwiZXhwIjoxNjU5MzU0MTE3LjY3NzY2MjR9._4u-jyYrK49CoagRqmWLggIXLMBGull26uLhyKsYOVo [GET] [in /usr/local/lib/python3.9/site-packages/flask/app.py:1455]
Traceback (most recent call last):
  File "/usr/local/lib/python3.9/site-packages/flask/app.py", line 2077, in wsgi_app
    response = self.full_dispatch_request()
  File "/usr/local/lib/python3.9/site-packages/flask/app.py", line 1525, in full_dispatch_request
    rv = self.handle_user_exception(e)
  File "/usr/local/lib/python3.9/site-packages/flask/app.py", line 1523, in full_dispatch_request
    rv = self.dispatch_request()
  File "/usr/local/lib/python3.9/site-packages/flask/app.py", line 1509, in dispatch_request
    return self.ensure_sync(self.view_functions[rule.endpoint])(**req.view_args)
  File "/root/python/flask/app/routes.py", line 182, in reset_password
    return render_template('reset_password.html',form=form)
  File "/usr/local/lib/python3.9/site-packages/flask/templating.py", line 149, in render_template
    ctx.app.jinja_env.get_or_select_template(template_name_or_list),
  File "/usr/local/lib/python3.9/site-packages/jinja2/environment.py", line 1081, in get_or_select_template
    return self.get_template(template_name_or_list, parent, globals)
  File "/usr/local/lib/python3.9/site-packages/jinja2/environment.py", line 1010, in get_template
    return self._load_template(name, globals)
  File "/usr/local/lib/python3.9/site-packages/jinja2/environment.py", line 969, in _load_template
    template = self.loader.load(self, name, self.make_globals(globals))
  File "/usr/local/lib/python3.9/site-packages/jinja2/loaders.py", line 138, in load
    code = environment.compile(source, name, filename)
  File "/usr/local/lib/python3.9/site-packages/jinja2/environment.py", line 768, in compile
    self.handle_exception(source=source_hint)
  File "/usr/local/lib/python3.9/site-packages/jinja2/environment.py", line 936, in handle_exception
    raise rewrite_traceback_stack(source=source)
  File "/root/python/flask/app/templates/reset_password.html", line 12, in template
    {% enfor %}
jinja2.exceptions.TemplateSyntaxError: Encountered unknown tag 'enfor'. Jinja was looking for the following tags: 'endfor' or 'else'. The innermost block that needs to be closed is 'for'.
2022-08-01 07:32:49,770 INFO: Microblog startup [in /root/python/flask/app/__init__.py:45]
2022-08-01 07:35:22,893 ERROR: Exception on /unfollow/susan [POST] [in /usr/local/lib/python3.9/site-packages/flask/app.py:1455]
Traceback (most recent call last):
  File "/usr/local/lib/python3.9/site-packages/flask/app.py", line 2077, in wsgi_app
    response = self.full_dispatch_request()
  File "/usr/local/lib/python3.9/site-packages/flask/app.py", line 1526, in full_dispatch_request
    return self.finalize_request(rv)
  File "/usr/local/lib/python3.9/site-packages/flask/app.py", line 1545, in finalize_request
    response = self.make_response(rv)
  File "/usr/local/lib/python3.9/site-packages/flask/app.py", line 1701, in make_response
    raise TypeError(
TypeError: The view function for 'unfollow' did not return a valid response. The function either returned None or ended without a return statement.
2022-08-01 07:38:16,688 INFO: Microblog startup [in /root/python/flask/app/__init__.py:45]
2022-08-01 07:38:21,825 ERROR: Exception on /unfollow/susan [POST] [in /usr/local/lib/python3.9/site-packages/flask/app.py:1455]
Traceback (most recent call last):
  File "/usr/local/lib/python3.9/site-packages/flask/app.py", line 2077, in wsgi_app
    response = self.full_dispatch_request()
  File "/usr/local/lib/python3.9/site-packages/flask/app.py", line 1526, in full_dispatch_request
    return self.finalize_request(rv)
  File "/usr/local/lib/python3.9/site-packages/flask/app.py", line 1545, in finalize_request
    response = self.make_response(rv)
  File "/usr/local/lib/python3.9/site-packages/flask/app.py", line 1701, in make_response
    raise TypeError(
TypeError: The view function for 'unfollow' did not return a valid response. The function either returned None or ended without a return statement.
2022-08-01 07:41:15,386 INFO: Microblog startup [in /root/python/flask/app/__init__.py:45]
